{
 "cells": [
  {
   "cell_type": "markdown",
   "id": "ff881eaa",
   "metadata": {},
   "source": [
    "Q1. Describe three applications for exception processing."
   ]
  },
  {
   "cell_type": "markdown",
   "id": "4ce16565",
   "metadata": {},
   "source": [
    "Exception processing is a critical aspect of error handling in programming. It allows developers to gracefully handle unexpected or exceptional situations that can arise during program execution. Here are three common applications for exception processing:\n",
    "\n",
    "1. **Input Validation and Error Handling**:\n",
    "   - When accepting user input, whether from a graphical user interface (GUI) or command-line interface (CLI), it's essential to validate and handle input errors.\n",
    "   - Applications often use exception processing to catch and handle input-related errors, such as invalid data types, out-of-range values, or missing input.\n",
    "   - For example, you can catch exceptions when converting user input to numeric types and provide informative error messages to guide the user.\n",
    "\n",
    "   ```python\n",
    "   try:\n",
    "       user_input = int(input(\"Enter a number: \"))\n",
    "   except ValueError as e:\n",
    "       print(f\"Error: {e}. Please enter a valid number.\")\n",
    "   ```\n",
    "\n",
    "2. **File Operations and I/O**:\n",
    "   - When working with files and performing input/output (I/O) operations, exceptions can occur due to various reasons, such as missing files, permission issues, or unexpected file content.\n",
    "   - Exception processing is used to handle these file-related errors gracefully and ensure that the program doesn't crash.\n",
    "   - For example, when opening a file for reading:\n",
    "\n",
    "   ```python\n",
    "   try:\n",
    "       with open(\"myfile.txt\", \"r\") as file:\n",
    "           data = file.read()\n",
    "   except FileNotFoundError:\n",
    "       print(\"Error: The file does not exist.\")\n",
    "   except IOError as e:\n",
    "       print(f\"Error: {e}. An I/O error occurred.\")\n",
    "   ```\n",
    "\n",
    "3. **Network Communications**:\n",
    "   - When working with network communications, such as making HTTP requests or connecting to remote services, exceptions are often used to handle network-related errors.\n",
    "   - Common network exceptions include connection errors, timeouts, and issues with remote servers.\n",
    "   - Exception processing ensures that the application can recover gracefully when network-related issues occur, preventing crashes and providing meaningful error messages to users.\n",
    "\n",
    "   ```python\n",
    "   import requests\n",
    "\n",
    "   try:\n",
    "       response = requests.get(\"https://example.com\")\n",
    "       response.raise_for_status()  # Raises an exception for HTTP errors\n",
    "   except requests.exceptions.RequestException as e:\n",
    "       print(f\"Error: {e}. Unable to fetch data from the server.\")\n",
    "   ```\n",
    "\n",
    "Exception processing is a crucial part of writing robust and reliable software. By handling exceptions effectively, developers can provide better user experiences and maintain the stability of their applications, even in the presence of unexpected issues."
   ]
  },
  {
   "cell_type": "markdown",
   "id": "9a997c49",
   "metadata": {},
   "source": [
    "Q2. What happens if you don&#39;t do something extra to treat an exception?\n"
   ]
  },
  {
   "cell_type": "markdown",
   "id": "4e1ee85f",
   "metadata": {},
   "source": [
    "If you don't handle or treat an exception in your code, the default behavior is for the exception to propagate up the call stack. This means that the exception will continue to propagate to higher levels of your program until it is either caught and handled by an exception handler or until it reaches the top-level of your program. If it reaches the top-level and is still unhandled, it will typically result in the termination of your program, and an error message (traceback) will be displayed.\n",
    "\n",
    "Here's a step-by-step explanation of what happens when an exception is not treated:\n",
    "\n",
    "1. **Exception Occurs**: When an exceptional condition occurs in your code (e.g., a division by zero, file not found, or an invalid operation), Python raises an exception.\n",
    "\n",
    "2. **Propagation**: If there is no immediate `try`...`except` block to handle the exception in the current scope or function, Python will propagate the exception up to the calling function or method. This continues until an exception handler is found or until it reaches the top-level scope.\n",
    "\n",
    "3. **Search for Exception Handler**: Python searches for an appropriate `try`...`except` block that can handle the exception based on the type of exception raised and the code structure. If no suitable exception handler is found, the exception continues to propagate.\n",
    "\n",
    "4. **Program Termination**: If the exception propagates all the way to the top-level of your program (e.g., the main module), and it is still unhandled, Python will terminate the program, and an error message (including a traceback) will be displayed. This traceback provides information about where the exception occurred and the call stack leading up to the exception.\n",
    "\n",
    "Here's a simple example to illustrate what happens when an exception is not treated:\n",
    "\n",
    "```python\n",
    "def divide(x, y):\n",
    "    return x / y\n",
    "\n",
    "result = divide(10, 0)  # Division by zero will raise a ZeroDivisionError\n",
    "print(result)  # This line will not be executed due to the unhandled exception\n",
    "```\n",
    "\n",
    "In this example, attempting to divide by zero raises a `ZeroDivisionError`. Since there is no `try`...`except` block to handle this exception, it propagates up the call stack and eventually terminates the program, preventing the execution of the `print(result)` line.\n",
    "\n",
    "To prevent program crashes and provide graceful error handling, it is essential to implement proper exception handling by using `try`...`except` blocks to catch and handle exceptions appropriately in your code."
   ]
  },
  {
   "cell_type": "markdown",
   "id": "cf83a8b2",
   "metadata": {},
   "source": [
    "Q3. What are your options for recovering from an exception in your script?"
   ]
  },
  {
   "cell_type": "markdown",
   "id": "b531fe95",
   "metadata": {},
   "source": [
    "When an exception occurs in your Python script, you have several options for recovering from it and handling the exceptional situation gracefully. Here are some common approaches:\n",
    "\n",
    "1. **Try...Except Blocks**: Use `try`...`except` blocks to catch and handle exceptions. Within a `try` block, you can place code that might raise an exception. In the corresponding `except` block, you can specify how to handle the exception.\n",
    "\n",
    "   ```python\n",
    "   try:\n",
    "       # Code that may raise an exception\n",
    "   except SomeExceptionType as e:\n",
    "       # Code to handle the exception, e.g., logging or providing a fallback\n",
    "   ```\n",
    "\n",
    "2. **Logging**: Log information about the exception to help with debugging and diagnostics. The `logging` module in Python provides a flexible way to log error messages and details when exceptions occur.\n",
    "\n",
    "   ```python\n",
    "   import logging\n",
    "\n",
    "   try:\n",
    "       # Code that may raise an exception\n",
    "   except SomeExceptionType as e:\n",
    "       # Log the exception details\n",
    "       logging.error(f\"An error occurred: {e}\")\n",
    "   ```\n",
    "\n",
    "3. **Fallback Values**: Provide default or fallback values when an exception occurs. This can allow your script to continue running with reasonable defaults, even in the presence of exceptions.\n",
    "\n",
    "   ```python\n",
    "   try:\n",
    "       result = operation_that_may_raise_an_exception()\n",
    "   except SomeExceptionType as e:\n",
    "       # Use a fallback value or provide a default result\n",
    "       result = default_value\n",
    "   ```\n",
    "\n",
    "4. **User-Friendly Error Messages**: When an exception occurs, display user-friendly error messages or notifications. This is especially important for applications with a graphical user interface (GUI) or when interacting with end-users.\n",
    "\n",
    "   ```python\n",
    "   try:\n",
    "       # Code that may raise an exception\n",
    "   except SomeExceptionType as e:\n",
    "       # Show an error message to the user\n",
    "       print(\"An error occurred: Please try again later.\")\n",
    "   ```\n",
    "\n",
    "5. **Graceful Termination**: In some cases, it may be appropriate to terminate the script gracefully when a critical exception occurs. You can do this by catching the exception at the top level and then exiting the script or closing resources.\n",
    "\n",
    "   ```python\n",
    "   try:\n",
    "       # Main script logic\n",
    "   except CriticalException as e:\n",
    "       # Handle the critical exception\n",
    "       print(\"Critical error: Exiting the script.\")\n",
    "       sys.exit(1)  # Exit with a non-zero status code\n",
    "   ```\n",
    "\n",
    "6. **Cleanup Resources**: If your script manages resources (e.g., files, network connections), use `try`...`finally` blocks to ensure that resources are properly cleaned up, even if an exception occurs.\n",
    "\n",
    "   ```python\n",
    "   try:\n",
    "       # Code that may raise an exception\n",
    "   except SomeExceptionType as e:\n",
    "       # Handle the exception\n",
    "   finally:\n",
    "       # Cleanup code (e.g., close files or connections)\n",
    "   ```\n",
    "\n",
    "7. **Custom Exception Classes**: Define custom exception classes to represent specific error conditions in your script. This can make exception handling more structured and informative.\n",
    "\n",
    "   ```python\n",
    "   class CustomError(Exception):\n",
    "       pass\n",
    "\n",
    "   try:\n",
    "       # Code that may raise a custom exception\n",
    "   except CustomError as e:\n",
    "       # Handle the custom exception\n",
    "   ```\n",
    "\n",
    "8. **Retry Mechanisms**: In situations where network-related or transient errors occur, you can implement retry mechanisms to retry the operation after a delay.\n",
    "\n",
    "   ```python\n",
    "   import time\n",
    "\n",
    "   retries = 3\n",
    "   while retries > 0:\n",
    "       try:\n",
    "           # Code that may raise an exception\n",
    "       except SomeExceptionType as e:\n",
    "           # Handle the exception\n",
    "           retries -= 1\n",
    "           time.sleep(5)  # Wait for a while before retrying\n",
    "   ```\n",
    "\n",
    "The choice of recovery method depends on the specific requirements and context of your script. It's important to select the most appropriate approach for handling exceptions based on the nature of the exceptions and the impact they have on your script's behavior and functionality."
   ]
  },
  {
   "cell_type": "markdown",
   "id": "dad157da",
   "metadata": {},
   "source": [
    "Q4. Describe two methods for triggering exceptions in your script."
   ]
  },
  {
   "cell_type": "markdown",
   "id": "21205e76",
   "metadata": {},
   "source": [
    "Certainly, here are two methods for triggering exceptions intentionally in your Python script:\n",
    "\n",
    "1. **Using the `raise` Statement**:\n",
    "   - The `raise` statement allows you to raise exceptions explicitly at a specific point in your code. You can raise built-in exceptions or custom exceptions.\n",
    "   - To raise an exception using `raise`, specify the exception type and, optionally, an error message.\n",
    "\n",
    "   ```python\n",
    "   def divide(x, y):\n",
    "       if y == 0:\n",
    "           raise ZeroDivisionError(\"Division by zero is not allowed\")\n",
    "       return x / y\n",
    "\n",
    "   try:\n",
    "       result = divide(10, 0)\n",
    "   except ZeroDivisionError as e:\n",
    "       print(f\"Error: {e}\")\n",
    "   ```\n",
    "\n",
    "   In this example, the `divide` function raises a `ZeroDivisionError` exception when the denominator (`y`) is zero. The `raise` statement is used to trigger the exception, and it includes an error message. The exception is then caught and handled in the `except` block.\n",
    "\n",
    "2. **Using the `assert` Statement**:\n",
    "   - The `assert` statement is used to raise an `AssertionError` exception when a specific condition is not met. It is commonly used for debugging and ensuring that certain conditions are valid during program execution.\n",
    "   - The `assert` statement has the form `assert condition, [message]`, where `condition` is the expression to evaluate, and `message` is an optional error message.\n",
    "\n",
    "   ```python\n",
    "   def calculate_average(values):\n",
    "       assert len(values) > 0, \"List must not be empty\"\n",
    "       total = sum(values)\n",
    "       return total / len(values)\n",
    "\n",
    "   try:\n",
    "       result = calculate_average([])\n",
    "   except AssertionError as e:\n",
    "       print(f\"Error: {e}\")\n",
    "   ```\n",
    "\n",
    "   In this example, the `calculate_average` function raises an `AssertionError` exception if the input list `values` is empty. The `assert` statement checks the condition (`len(values) > 0`) and raises the exception with an error message if the condition is not satisfied. The exception is then caught and handled in the `except` block.\n",
    "\n",
    "Both of these methods allow you to trigger exceptions intentionally in your script. The choice between them depends on the context and purpose of triggering the exception. The `raise` statement is more versatile and can be used to raise custom exceptions, while the `assert` statement is primarily used for debugging and enforcing conditions in your code."
   ]
  },
  {
   "cell_type": "markdown",
   "id": "fee4eb2b",
   "metadata": {},
   "source": [
    "Q5. Identify two methods for specifying actions to be executed at termination time, regardless of\n",
    "whether or not an exception exists."
   ]
  },
  {
   "cell_type": "markdown",
   "id": "d8dead0e",
   "metadata": {},
   "source": [
    "In Python, you can specify actions to be executed at termination time, regardless of whether or not an exception occurs, using two methods: the `finally` block and the `atexit` module.\n",
    "\n",
    "1. **Using the `finally` Block**:\n",
    "   - The `finally` block is a construct that allows you to specify code that will always execute, regardless of whether an exception occurred within the associated `try` block.\n",
    "   - This is commonly used for tasks such as cleanup, resource release, or ensuring that certain actions are taken before exiting a block of code.\n",
    "\n",
    "   ```python\n",
    "   try:\n",
    "       # Code that may raise an exception\n",
    "   except SomeException as e:\n",
    "       # Handle the exception\n",
    "   finally:\n",
    "       # Code that always executes, whether there was an exception or not\n",
    "   ```\n",
    "\n",
    "   Here's an example using file handling where the `finally` block ensures that the file is closed, regardless of whether an exception occurs:\n",
    "\n",
    "   ```python\n",
    "   try:\n",
    "       file = open(\"example.txt\", \"r\")\n",
    "       # Read or manipulate the file contents\n",
    "   except FileNotFoundError:\n",
    "       print(\"File not found.\")\n",
    "   finally:\n",
    "       if file:\n",
    "           file.close()  # Ensure the file is closed\n",
    "   ```\n",
    "\n",
    "2. **Using the `atexit` Module**:\n",
    "   - The `atexit` module in Python allows you to register functions or methods that should be executed when the program is about to exit, whether normally or due to an unhandled exception.\n",
    "   - This is useful for performing cleanup tasks or saving program state before the script exits.\n",
    "\n",
    "   ```python\n",
    "   import atexit\n",
    "\n",
    "   def cleanup():\n",
    "       # Code to perform cleanup actions\n",
    "       print(\"Cleanup: Closing resources\")\n",
    "\n",
    "   # Register the cleanup function to be called at exit\n",
    "   atexit.register(cleanup)\n",
    "\n",
    "   # Main script logic\n",
    "   print(\"Script is running...\")\n",
    "\n",
    "   # Simulate an unhandled exception\n",
    "   raise ValueError(\"An exception occurred\")\n",
    "   ```\n",
    "\n",
    "   In this example, the `cleanup` function is registered using `atexit.register()`. It will be called automatically when the script exits, regardless of whether an exception occurs.\n",
    "\n",
    "Both of these methods (`finally` block and `atexit` module) ensure that specified actions are taken at termination time, even if an exception exists. The choice between them depends on your specific requirements and whether you want to handle cleanup at the block level (`finally`) or at the script level (`atexit`)."
   ]
  },
  {
   "cell_type": "code",
   "execution_count": null,
   "id": "35e36879",
   "metadata": {},
   "outputs": [],
   "source": []
  }
 ],
 "metadata": {
  "kernelspec": {
   "display_name": "Python 3 (ipykernel)",
   "language": "python",
   "name": "python3"
  },
  "language_info": {
   "codemirror_mode": {
    "name": "ipython",
    "version": 3
   },
   "file_extension": ".py",
   "mimetype": "text/x-python",
   "name": "python",
   "nbconvert_exporter": "python",
   "pygments_lexer": "ipython3",
   "version": "3.9.13"
  }
 },
 "nbformat": 4,
 "nbformat_minor": 5
}
